2023-12-13 17:15:26,449 - ERROR - /home/herilala/Bureau/HEI/Prog5/exeption/server.py:251 - division by zero
2023-12-13 17:19:04,963 - ERROR - /home/herilala/Bureau/HEI/Prog5/exeption/server.py:251 - division by zero
2023-12-13 17:19:04,965 - ERROR - /home/herilala/Bureau/HEI/Prog5/exeption/server.py:222 - Traceback (most recent call last):
  File "/home/herilala/Bureau/HEI/Prog5/exeption/server.py", line 249, in divs_by_0
    x = 1 / 0
ZeroDivisionError: division by zero

During handling of the above exception, another exception occurred:

Traceback (most recent call last):
  File "/home/herilala/.pyenv/versions/3.10.13/lib/python3.10/site-packages/starlette/middleware/exceptions.py", line 68, in __call__
    await self.app(scope, receive, sender)
  File "/home/herilala/.pyenv/versions/3.10.13/lib/python3.10/site-packages/fastapi/middleware/asyncexitstack.py", line 20, in __call__
    raise e
  File "/home/herilala/.pyenv/versions/3.10.13/lib/python3.10/site-packages/fastapi/middleware/asyncexitstack.py", line 17, in __call__
    await self.app(scope, receive, send)
  File "/home/herilala/.pyenv/versions/3.10.13/lib/python3.10/site-packages/starlette/routing.py", line 718, in __call__
    await route.handle(scope, receive, send)
  File "/home/herilala/.pyenv/versions/3.10.13/lib/python3.10/site-packages/starlette/routing.py", line 276, in handle
    await self.app(scope, receive, send)
  File "/home/herilala/.pyenv/versions/3.10.13/lib/python3.10/site-packages/starlette/routing.py", line 66, in app
    response = await func(request)
  File "/home/herilala/.pyenv/versions/3.10.13/lib/python3.10/site-packages/fastapi/routing.py", line 274, in app
    raw_response = await run_endpoint_function(
  File "/home/herilala/.pyenv/versions/3.10.13/lib/python3.10/site-packages/fastapi/routing.py", line 193, in run_endpoint_function
    return await run_in_threadpool(dependant.call, **values)
  File "/home/herilala/.pyenv/versions/3.10.13/lib/python3.10/site-packages/starlette/concurrency.py", line 41, in run_in_threadpool
    return await anyio.to_thread.run_sync(func, *args)
  File "/home/herilala/.pyenv/versions/3.10.13/lib/python3.10/site-packages/anyio/to_thread.py", line 33, in run_sync
    return await get_asynclib().run_sync_in_worker_thread(
  File "/home/herilala/.pyenv/versions/3.10.13/lib/python3.10/site-packages/anyio/_backends/_asyncio.py", line 877, in run_sync_in_worker_thread
    return await future
  File "/home/herilala/.pyenv/versions/3.10.13/lib/python3.10/site-packages/anyio/_backends/_asyncio.py", line 807, in run
    result = context.run(func, *args)
  File "/home/herilala/Bureau/HEI/Prog5/exeption/server.py", line 252, in divs_by_0
    raise raise_exception(
fastapi.exceptions.HTTPException

2023-12-13 17:19:04,966 - ERROR - /home/herilala/Bureau/HEI/Prog5/exeption/server.py:223 -  --- --- --- --- --- --- --- --- ---


